'use strict';
/*------------------------------------------------------------------------------
Full description at: https://github.com/HackYourFuture/Homework/tree/main/3-UsingAPIs/Week1#exercise-3-roll-a-die

- Run the unmodified program and confirm that problem described occurs.
- Refactor the `rollDie()` function from callback-based to returning a
  promise.
- Change the calls to `callback()` to calls to `resolve()` and `reject()`.
- Refactor the code that call `rollDie()` to use the promise it returns.
- Does the problem described above still occur? If not, what would be your
  explanation? Add your answer as a comment to be bottom of the file.
------------------------------------------------------------------------------*/

function rollDie() {
  // Compute a random number of rolls (3-10) that the die MUST complete
  return new Promise((resolve, reject) => {
    const randomRollsToDo = Math.floor(Math.random() * 8) + 3;
    console.log(`Die scheduled for ${randomRollsToDo} rolls...`);
    const rollOnce = (roll) => {
      // Compute a random die value for the current roll
      const value = Math.floor(Math.random() * 6) + 1;
      console.log(`Die value is now: ${value}`);

      // Use callback to notify that the die rolled off the table after 6 rolls
      if (roll > 6) {
        reject(new Error('Oops... Die rolled off the table.'));
      }

      // Use callback to communicate the final die value once finished rolling
      if (roll === randomRollsToDo) {
        resolve(`Success! Die settled on ${value}.`);
      }

      // Schedule the next roll todo until no more rolls to do
      if (roll < randomRollsToDo) {
        setTimeout(() => rollOnce(roll + 1), 500);
      }
    };
    rollOnce(1);
  });

  // Start the initial roll
}

function main() {
  rollDie()
    .then((successMessage) => console.log(successMessage))
    .catch((error) => console.log(error.message));
}

// ! Do not change or remove the code below
if (process.env.NODE_ENV !== 'test') {
  main();
}
module.exports = rollDie;

// The indicated probelm does not occur with promises because in call back it was calling success and fail at the same time if it was more than 6 so it will print both at the end,
// but another problem arises which is that once a promise is resolved or rejected it does not resolve or reject again, thus if the die rolled more than 7 times it will give a reject but will not give any success later
